[2023-09-21T00:51:58.740+0000] {taskinstance.py:1157} INFO - Dependencies all met for dep_context=non-requeueable deps ti=<TaskInstance: student_semantic.send_to_snowflake manual__2023-09-21T00:51:53.296700+00:00 [queued]>
[2023-09-21T00:51:58.747+0000] {taskinstance.py:1157} INFO - Dependencies all met for dep_context=requeueable deps ti=<TaskInstance: student_semantic.send_to_snowflake manual__2023-09-21T00:51:53.296700+00:00 [queued]>
[2023-09-21T00:51:58.747+0000] {taskinstance.py:1359} INFO - Starting attempt 1 of 1
[2023-09-21T00:51:58.761+0000] {taskinstance.py:1380} INFO - Executing <Task(PythonOperator): send_to_snowflake> on 2023-09-21 00:51:53.296700+00:00
[2023-09-21T00:51:58.767+0000] {standard_task_runner.py:57} INFO - Started process 851 to run task
[2023-09-21T00:51:58.770+0000] {standard_task_runner.py:84} INFO - Running: ['***', 'tasks', 'run', 'student_semantic', 'send_to_snowflake', 'manual__2023-09-21T00:51:53.296700+00:00', '--job-id', '383', '--raw', '--subdir', 'DAGS_FOLDER/student_semantic.py', '--cfg-path', '/tmp/tmp88tu4vic']
[2023-09-21T00:51:58.772+0000] {standard_task_runner.py:85} INFO - Job 383: Subtask send_to_snowflake
[2023-09-21T00:51:58.809+0000] {task_command.py:415} INFO - Running <TaskInstance: student_semantic.send_to_snowflake manual__2023-09-21T00:51:53.296700+00:00 [running]> on host fd67d4db30a8
[2023-09-21T00:51:58.870+0000] {taskinstance.py:1660} INFO - Exporting env vars: AIRFLOW_CTX_DAG_OWNER='***' AIRFLOW_CTX_DAG_ID='student_semantic' AIRFLOW_CTX_TASK_ID='send_to_snowflake' AIRFLOW_CTX_EXECUTION_DATE='2023-09-21T00:51:53.296700+00:00' AIRFLOW_CTX_TRY_NUMBER='1' AIRFLOW_CTX_DAG_RUN_ID='manual__2023-09-21T00:51:53.296700+00:00'
[2023-09-21T00:51:58.872+0000] {connection.py:314} INFO - Snowflake Connector for Python Version: 3.1.1, Python Version: 3.8.18, Platform: Linux-5.10.16.3-microsoft-standard-WSL2-x86_64-with-glibc2.2.5
[2023-09-21T00:51:58.872+0000] {connection.py:1050} INFO - This connection is in OCSP Fail Open Mode. TLS Certificates would be checked for validity and revocation status. Any other Certificate Revocation related exceptions or OCSP Responder failures would be disregarded in favor of connectivity.
[2023-09-21T00:51:58.873+0000] {connection.py:1060} INFO - THIS CONNECTION IS IN INSECURE MODE. IT MEANS THE CERTIFICATE WILL BE VALIDATED BUT THE CERTIFICATE REVOCATION STATUS WILL NOT BE CHECKED.
[2023-09-21T00:51:58.873+0000] {connection.py:1068} INFO - Setting use_openssl_only mode to False
[2023-09-21T00:51:59.593+0000] {ssl_wrap_socket.py:100} INFO - THIS CONNECTION IS IN INSECURE MODE. IT MEANS THE CERTIFICATE WILL BE VALIDATED BUT THE CERTIFICATE REVOCATION STATUS WILL NOT BE CHECKED.
[2023-09-21T00:51:59.837+0000] {taskinstance.py:1935} ERROR - Task failed with exception
Traceback (most recent call last):
  File "/home/airflow/.local/lib/python3.8/site-packages/snowflake/connector/auth/_auth.py", line 250, in authenticate
    ret = self._rest._post_request(
  File "/home/airflow/.local/lib/python3.8/site-packages/snowflake/connector/network.py", line 730, in _post_request
    ret = self.fetch(
  File "/home/airflow/.local/lib/python3.8/site-packages/snowflake/connector/network.py", line 849, in fetch
    ret = self._request_exec_wrapper(
  File "/home/airflow/.local/lib/python3.8/site-packages/snowflake/connector/network.py", line 987, in _request_exec_wrapper
    raise e
  File "/home/airflow/.local/lib/python3.8/site-packages/snowflake/connector/network.py", line 891, in _request_exec_wrapper
    return_object = self._request_exec(
  File "/home/airflow/.local/lib/python3.8/site-packages/snowflake/connector/network.py", line 1189, in _request_exec
    raise err
  File "/home/airflow/.local/lib/python3.8/site-packages/snowflake/connector/network.py", line 1110, in _request_exec
    raise ForbiddenError
snowflake.connector.errors.ForbiddenError: HTTP 403: Forbidden

During handling of the above exception, another exception occurred:

Traceback (most recent call last):
  File "/home/airflow/.local/lib/python3.8/site-packages/airflow/operators/python.py", line 192, in execute
    return_value = self.execute_callable()
  File "/home/airflow/.local/lib/python3.8/site-packages/airflow/operators/python.py", line 209, in execute_callable
    return self.python_callable(*self.op_args, **self.op_kwargs)
  File "/opt/airflow/dags/packages/student_semantic/student_semantic.py", line 157, in send_to_snowflake
    conn = connect(
  File "/home/airflow/.local/lib/python3.8/site-packages/snowflake/connector/__init__.py", line 51, in Connect
    return SnowflakeConnection(**kwargs)
  File "/home/airflow/.local/lib/python3.8/site-packages/snowflake/connector/connection.py", line 353, in __init__
    self.connect(**kwargs)
  File "/home/airflow/.local/lib/python3.8/site-packages/snowflake/connector/connection.py", line 625, in connect
    self.__open_connection()
  File "/home/airflow/.local/lib/python3.8/site-packages/snowflake/connector/connection.py", line 898, in __open_connection
    self.authenticate_with_retry(self.auth_class)
  File "/home/airflow/.local/lib/python3.8/site-packages/snowflake/connector/connection.py", line 1167, in authenticate_with_retry
    self._authenticate(auth_instance)
  File "/home/airflow/.local/lib/python3.8/site-packages/snowflake/connector/connection.py", line 1193, in _authenticate
    auth.authenticate(
  File "/home/airflow/.local/lib/python3.8/site-packages/snowflake/connector/auth/_auth.py", line 259, in authenticate
    raise err.__class__(
snowflake.connector.errors.ForbiddenError: 250001 (08001): None: Failed to connect to DB. Verify the account name is correct: hc45535.snowflakecomputing.com:443. HTTP 403: Forbidden
[2023-09-21T00:51:59.843+0000] {taskinstance.py:1398} INFO - Marking task as FAILED. dag_id=student_semantic, task_id=send_to_snowflake, execution_date=20230921T005153, start_date=20230921T005158, end_date=20230921T005159
[2023-09-21T00:51:59.855+0000] {standard_task_runner.py:104} ERROR - Failed to execute job 383 for task send_to_snowflake (250001 (08001): None: Failed to connect to DB. Verify the account name is correct: hc45535.snowflakecomputing.com:443. HTTP 403: Forbidden; 851)
[2023-09-21T00:51:59.868+0000] {local_task_job_runner.py:228} INFO - Task exited with return code 1
[2023-09-21T00:51:59.881+0000] {taskinstance.py:2776} INFO - 0 downstream tasks scheduled from follow-on schedule check
