[2023-09-20T20:25:26.478+0000] {taskinstance.py:1157} INFO - Dependencies all met for dep_context=non-requeueable deps ti=<TaskInstance: student_semantic.send_to_processed_lake manual__2023-09-20T20:25:25.455213+00:00 [queued]>
[2023-09-20T20:25:26.486+0000] {taskinstance.py:1157} INFO - Dependencies all met for dep_context=requeueable deps ti=<TaskInstance: student_semantic.send_to_processed_lake manual__2023-09-20T20:25:25.455213+00:00 [queued]>
[2023-09-20T20:25:26.487+0000] {taskinstance.py:1359} INFO - Starting attempt 1 of 1
[2023-09-20T20:25:26.499+0000] {taskinstance.py:1380} INFO - Executing <Task(PythonOperator): send_to_processed_lake> on 2023-09-20 20:25:25.455213+00:00
[2023-09-20T20:25:26.505+0000] {standard_task_runner.py:57} INFO - Started process 1736 to run task
[2023-09-20T20:25:26.509+0000] {standard_task_runner.py:84} INFO - Running: ['***', 'tasks', 'run', 'student_semantic', 'send_to_processed_lake', 'manual__2023-09-20T20:25:25.455213+00:00', '--job-id', '172', '--raw', '--subdir', 'DAGS_FOLDER/student_semantic.py', '--cfg-path', '/tmp/tmpku64fii8']
[2023-09-20T20:25:26.511+0000] {standard_task_runner.py:85} INFO - Job 172: Subtask send_to_processed_lake
[2023-09-20T20:25:26.559+0000] {task_command.py:415} INFO - Running <TaskInstance: student_semantic.send_to_processed_lake manual__2023-09-20T20:25:25.455213+00:00 [running]> on host 6086152831d6
[2023-09-20T20:25:26.827+0000] {taskinstance.py:1660} INFO - Exporting env vars: AIRFLOW_CTX_DAG_OWNER='***' AIRFLOW_CTX_DAG_ID='student_semantic' AIRFLOW_CTX_TASK_ID='send_to_processed_lake' AIRFLOW_CTX_EXECUTION_DATE='2023-09-20T20:25:25.455213+00:00' AIRFLOW_CTX_TRY_NUMBER='1' AIRFLOW_CTX_DAG_RUN_ID='manual__2023-09-20T20:25:25.455213+00:00'
[2023-09-20T20:25:26.866+0000] {taskinstance.py:1935} ERROR - Task failed with exception
Traceback (most recent call last):
  File "/home/airflow/.local/lib/python3.8/site-packages/pandas/core/indexes/base.py", line 3653, in get_loc
    return self._engine.get_loc(casted_key)
  File "pandas/_libs/index.pyx", line 147, in pandas._libs.index.IndexEngine.get_loc
  File "pandas/_libs/index.pyx", line 176, in pandas._libs.index.IndexEngine.get_loc
  File "pandas/_libs/hashtable_class_helper.pxi", line 7080, in pandas._libs.hashtable.PyObjectHashTable.get_item
  File "pandas/_libs/hashtable_class_helper.pxi", line 7088, in pandas._libs.hashtable.PyObjectHashTable.get_item
KeyError: 0

The above exception was the direct cause of the following exception:

Traceback (most recent call last):
  File "/home/airflow/.local/lib/python3.8/site-packages/airflow/operators/python.py", line 192, in execute
    return_value = self.execute_callable()
  File "/home/airflow/.local/lib/python3.8/site-packages/airflow/operators/python.py", line 209, in execute_callable
    return self.python_callable(*self.op_args, **self.op_kwargs)
  File "/opt/airflow/dags/packages/student_semantic/student_semantic.py", line 118, in send_data_to_processed
    df_processed = xcom_obj[0]
  File "/home/airflow/.local/lib/python3.8/site-packages/pandas/core/frame.py", line 3761, in __getitem__
    indexer = self.columns.get_loc(key)
  File "/home/airflow/.local/lib/python3.8/site-packages/pandas/core/indexes/base.py", line 3655, in get_loc
    raise KeyError(key) from err
KeyError: 0
[2023-09-20T20:25:26.877+0000] {taskinstance.py:1398} INFO - Marking task as FAILED. dag_id=student_semantic, task_id=send_to_processed_lake, execution_date=20230920T202525, start_date=20230920T202526, end_date=20230920T202526
[2023-09-20T20:25:26.888+0000] {standard_task_runner.py:104} ERROR - Failed to execute job 172 for task send_to_processed_lake (0; 1736)
[2023-09-20T20:25:26.922+0000] {local_task_job_runner.py:228} INFO - Task exited with return code 1
[2023-09-20T20:25:26.937+0000] {taskinstance.py:2776} INFO - 0 downstream tasks scheduled from follow-on schedule check
