[2023-09-21T02:19:41.005+0000] {taskinstance.py:1157} INFO - Dependencies all met for dep_context=non-requeueable deps ti=<TaskInstance: student_semantic.f manual__2023-09-21T02:19:34.008086+00:00 [queued]>
[2023-09-21T02:19:41.012+0000] {taskinstance.py:1157} INFO - Dependencies all met for dep_context=requeueable deps ti=<TaskInstance: student_semantic.f manual__2023-09-21T02:19:34.008086+00:00 [queued]>
[2023-09-21T02:19:41.012+0000] {taskinstance.py:1359} INFO - Starting attempt 1 of 1
[2023-09-21T02:19:41.024+0000] {taskinstance.py:1380} INFO - Executing <Task(CopyFromExternalStageToSnowflakeOperator): f> on 2023-09-21 02:19:34.008086+00:00
[2023-09-21T02:19:41.030+0000] {standard_task_runner.py:57} INFO - Started process 3377 to run task
[2023-09-21T02:19:41.033+0000] {standard_task_runner.py:84} INFO - Running: ['***', 'tasks', 'run', 'student_semantic', 'f', 'manual__2023-09-21T02:19:34.008086+00:00', '--job-id', '557', '--raw', '--subdir', 'DAGS_FOLDER/student_semantic.py', '--cfg-path', '/tmp/tmpipt0ou9b']
[2023-09-21T02:19:41.035+0000] {standard_task_runner.py:85} INFO - Job 557: Subtask f
[2023-09-21T02:19:41.073+0000] {task_command.py:415} INFO - Running <TaskInstance: student_semantic.f manual__2023-09-21T02:19:34.008086+00:00 [running]> on host fd67d4db30a8
[2023-09-21T02:19:41.145+0000] {taskinstance.py:1660} INFO - Exporting env vars: AIRFLOW_CTX_DAG_OWNER='***' AIRFLOW_CTX_DAG_ID='student_semantic' AIRFLOW_CTX_TASK_ID='f' AIRFLOW_CTX_EXECUTION_DATE='2023-09-21T02:19:34.008086+00:00' AIRFLOW_CTX_TRY_NUMBER='1' AIRFLOW_CTX_DAG_RUN_ID='manual__2023-09-21T02:19:34.008086+00:00'
[2023-09-21T02:19:41.146+0000] {copy_into_snowflake.py:139} INFO - Executing COPY command...
[2023-09-21T02:19:41.155+0000] {base.py:73} INFO - Using connection ID 'snowflake_conn_id' for task execution.
[2023-09-21T02:19:41.155+0000] {connection.py:314} INFO - Snowflake Connector for Python Version: 3.1.1, Python Version: 3.8.18, Platform: Linux-5.10.16.3-microsoft-standard-WSL2-x86_64-with-glibc2.2.5
[2023-09-21T02:19:41.156+0000] {connection.py:1050} INFO - This connection is in OCSP Fail Open Mode. TLS Certificates would be checked for validity and revocation status. Any other Certificate Revocation related exceptions or OCSP Responder failures would be disregarded in favor of connectivity.
[2023-09-21T02:19:41.156+0000] {connection.py:1068} INFO - Setting use_openssl_only mode to False
[2023-09-21T02:19:42.031+0000] {connection.py:547} WARNING - Certificate did not match expected hostname: hc45535.us-central1.snowflakecomputing.com. Certificate: {'subject': ((('commonName', '*.prod3.us-west-2.snowflakecomputing.com'),),), 'subjectAltName': [('DNS', '*.prod3.us-west-2.snowflakecomputing.com'), ('DNS', '*.us-west-2.snowflakecomputing.com'), ('DNS', '*.global.snowflakecomputing.com'), ('DNS', '*.snowflakecomputing.com'), ('DNS', '*.prod3.us-west-2.aws.snowflakecomputing.com')]}
[2023-09-21T02:19:42.032+0000] {connectionpool.py:812} WARNING - Retrying (Retry(total=0, connect=None, read=None, redirect=None, status=None)) after connection broken by 'SSLError(CertificateError("hostname 'hc45535.us-central1.snowflakecomputing.com' doesn't match either of '*.prod3.us-west-2.snowflakecomputing.com', '*.us-west-2.snowflakecomputing.com', '*.global.snowflakecomputing.com', '*.snowflakecomputing.com', '*.prod3.us-west-2.aws.snowflakecomputing.com'"))': /session/authenticator-request?request_guid=133bb77b-c486-409a-86aa-6b8cc2fb9270
[2023-09-21T02:19:42.802+0000] {connection.py:547} WARNING - Certificate did not match expected hostname: hc45535.us-central1.snowflakecomputing.com. Certificate: {'subject': ((('commonName', '*.prod3.us-west-2.snowflakecomputing.com'),),), 'subjectAltName': [('DNS', '*.prod3.us-west-2.snowflakecomputing.com'), ('DNS', '*.us-west-2.snowflakecomputing.com'), ('DNS', '*.global.snowflakecomputing.com'), ('DNS', '*.snowflakecomputing.com'), ('DNS', '*.prod3.us-west-2.aws.snowflakecomputing.com')]}
[2023-09-21T02:19:42.804+0000] {network.py:1037} ERROR - Failed to get the response. Hanging? method: post, url: https://hc45535.us-central1.snowflakecomputing.com:443/session/authenticator-request?request_guid=133bb77b-c486-409a-86aa-6b8cc2fb9270, headers:{'Content-Type': 'application/json', 'accept': 'application/json', 'User-Agent': 'PythonConnector/3.1.1 (Linux-5.10.16.3-microsoft-standard-WSL2-x86_64-with-glibc2.2.5) CPython/3.8.18', 'Content-Encoding': 'gzip'}, data: {"data": {"CLIENT_APP_ID": "PythonConnector", "CLIENT_APP_VERSION": "3.1.1", "SVN_REVISION": null, "ACCOUNT_NAME": "hc45535", "LOGIN_NAME": "edumzs", "CLIENT_ENVIRONMENT": {"APPLICATION": "AIRFLOW", "OS": "Linux", "OS_VERSION": "Linux-5.10.16.3-microsoft-standard-WSL2-x86_64-with-glibc2.2.5", "PYTHON_VERSION": "3.8.18", "PYTHON_RUNTIME": "CPython", "PYTHON_COMPILER": "GCC 10.2.1 20210110", "OCSP_MODE": "FAIL_OPEN", "TRACING": 20, "LOGIN_TIMEOUT": 120, "NETWORK_TIMEOUT": null}, "AUTHENTICATOR": "EXTERNALBROWSER", "BROWSER_MODE_REDIRECT_PORT": "38387"}}
[2023-09-21T02:19:42.811+0000] {taskinstance.py:1935} ERROR - Task failed with exception
Traceback (most recent call last):
  File "/home/airflow/.local/lib/python3.8/site-packages/airflow/providers/snowflake/transfers/copy_into_snowflake.py", line 140, in execute
    snowflake_hook.run(sql=sql, autocommit=self.autocommit)
  File "/home/airflow/.local/lib/python3.8/site-packages/airflow/providers/snowflake/hooks/snowflake.py", line 409, in run
    with closing(self.get_conn()) as conn:
  File "/home/airflow/.local/lib/python3.8/site-packages/airflow/providers/snowflake/hooks/snowflake.py", line 303, in get_conn
    conn = connector.connect(**conn_config)
  File "/home/airflow/.local/lib/python3.8/site-packages/snowflake/connector/__init__.py", line 51, in Connect
    return SnowflakeConnection(**kwargs)
  File "/home/airflow/.local/lib/python3.8/site-packages/snowflake/connector/connection.py", line 353, in __init__
    self.connect(**kwargs)
  File "/home/airflow/.local/lib/python3.8/site-packages/snowflake/connector/connection.py", line 625, in connect
    self.__open_connection()
  File "/home/airflow/.local/lib/python3.8/site-packages/snowflake/connector/connection.py", line 898, in __open_connection
    self.authenticate_with_retry(self.auth_class)
  File "/home/airflow/.local/lib/python3.8/site-packages/snowflake/connector/connection.py", line 1167, in authenticate_with_retry
    self._authenticate(auth_instance)
  File "/home/airflow/.local/lib/python3.8/site-packages/snowflake/connector/connection.py", line 1179, in _authenticate
    auth_instance.prepare(
  File "/home/airflow/.local/lib/python3.8/site-packages/snowflake/connector/auth/webbrowser.py", line 137, in prepare
    sso_url = self._get_sso_url(
  File "/home/airflow/.local/lib/python3.8/site-packages/snowflake/connector/auth/webbrowser.py", line 404, in _get_sso_url
    ret = conn._rest._post_request(
  File "/home/airflow/.local/lib/python3.8/site-packages/snowflake/connector/network.py", line 730, in _post_request
    ret = self.fetch(
  File "/home/airflow/.local/lib/python3.8/site-packages/snowflake/connector/network.py", line 849, in fetch
    ret = self._request_exec_wrapper(
  File "/home/airflow/.local/lib/python3.8/site-packages/snowflake/connector/network.py", line 987, in _request_exec_wrapper
    raise e
  File "/home/airflow/.local/lib/python3.8/site-packages/snowflake/connector/network.py", line 902, in _request_exec_wrapper
    self._handle_unknown_error(method, full_url, headers, data, conn)
  File "/home/airflow/.local/lib/python3.8/site-packages/snowflake/connector/network.py", line 1042, in _handle_unknown_error
    Error.errorhandler_wrapper(
  File "/home/airflow/.local/lib/python3.8/site-packages/snowflake/connector/errors.py", line 290, in errorhandler_wrapper
    handed_over = Error.hand_to_other_handler(
  File "/home/airflow/.local/lib/python3.8/site-packages/snowflake/connector/errors.py", line 348, in hand_to_other_handler
    connection.errorhandler(connection, cursor, error_class, error_value)
  File "/home/airflow/.local/lib/python3.8/site-packages/snowflake/connector/errors.py", line 221, in default_errorhandler
    raise error_class(
snowflake.connector.errors.OperationalError: 250003: 250003: Failed to get the response. Hanging? method: post, url: https://hc45535.us-central1.snowflakecomputing.com:443/session/authenticator-request?request_guid=133bb77b-c486-409a-86aa-6b8cc2fb9270
[2023-09-21T02:19:42.818+0000] {taskinstance.py:1398} INFO - Marking task as FAILED. dag_id=student_semantic, task_id=f, execution_date=20230921T021934, start_date=20230921T021941, end_date=20230921T021942
[2023-09-21T02:19:42.830+0000] {standard_task_runner.py:104} ERROR - Failed to execute job 557 for task f (250003: 250003: Failed to get the response. Hanging? method: post, url: https://hc45535.us-central1.snowflakecomputing.com:443/session/authenticator-request?request_guid=133bb77b-c486-409a-86aa-6b8cc2fb9270; 3377)
[2023-09-21T02:19:42.859+0000] {local_task_job_runner.py:228} INFO - Task exited with return code 1
[2023-09-21T02:19:42.872+0000] {taskinstance.py:2776} INFO - 0 downstream tasks scheduled from follow-on schedule check
